<?xml version="1.0" ?>
<!-- =================================================================================== -->
<!-- |    This document was autogenerated by xacro from spb_urdf.xacro                 | -->
<!-- |    EDITING THIS FILE BY HAND IS NOT RECOMMENDED                                 | -->
<!-- =================================================================================== -->
<robot name="spb_urdf">
  <!-- Specify some standard inertial calculations https://en.wikipedia.org/wiki/List_of_moments_of_inertia -->
  <!-- These make use of xacro's mathematical functionality -->
  <material name="Black">
    <color rgba="0.0 0.0 0.0 1.0"/>
  </material>
  <material name="Dark">
    <color rgba="0.3 0.3 0.3 1.0"/>
  </material>
  <material name="Light_black">
    <color rgba="0.4 0.4 0.4 1.0"/>
  </material>
  <material name="Blue">
    <color rgba="0.0 0.0 0.8 1.0"/>
  </material>
  <material name="Green">
    <color rgba="0.0 0.8 0.0 1.0"/>
  </material>
  <material name="Grey">
    <color rgba="0.5 0.5 0.5 1.0"/>
  </material>
  <material name="Orange">
    <color rgba="1.0 0.4235294117647059 0.0392156862745098 1.0"/>
  </material>
  <material name="Brown">
    <color rgba="0.8705882352941177 0.8117647058823529 0.7647058823529411 1.0"/>
  </material>
  <material name="Red">
    <color rgba="0.8 0.0 0.0 1.0"/>
  </material>
  <material name="White">
    <color rgba="1.0 1.0 1.0 1.0"/>
  </material>
  <material name="Cyan">
    <color rgba="0 1.0 1.0 1.0"/>
  </material>
  <!-- Robot Base -->
  <link name="base_link">
    <visual>
      <geometry>
        <box size="0.42 0.31 0.18"/>
      </geometry>
      <material name="Orange"/>
    </visual>
    <collision>
      <geometry>
        <box size="0.42 0.31 0.18"/>
      </geometry>
    </collision>
    <inertial>
      <origin rpy="0 0 0" xyz="0 0 0"/>
      <mass value="1.0"/>
      <inertia ixx="0.010708333333333334" ixy="0.0" ixz="0.0" iyy="0.0174" iyz="0.0" izz="0.02270833333333333"/>
    </inertial>
  </link>
  <!-- Robot Footprint -->
  <link name="base_footprint">
    <inertial>
      <origin rpy="0 0 0" xyz="0 0 0"/>
      <mass value="0"/>
      <inertia ixx="0.0" ixy="0.0" ixz="0.0" iyy="0.0" iyz="0.0" izz="0.0"/>
    </inertial>
  </link>
  <joint name="base_joint" type="fixed">
    <parent link="base_footprint"/>
    <child link="base_link"/>
    <origin rpy="0 0 0" xyz="0.0 0.0 0.15000000000000002"/>
  </joint>
  <link name="wheel_left_link">
    <visual>
      <origin rpy="1.5707963267948966 0 0" xyz="0 0 0"/>
      <geometry>
        <cylinder length="0.04" radius="0.1"/>
      </geometry>
      <material name="Cyan"/>
    </visual>
    <collision>
      <origin rpy="1.5707963267948966 0 0" xyz="0 0 0"/>
      <geometry>
        <cylinder length="0.04" radius="0.1"/>
      </geometry>
    </collision>
    <inertial>
      <origin rpy="0 0 0" xyz="0 0 0"/>
      <mass value="0.05"/>
      <inertia ixx="0.00013166666666666668" ixy="0.0" ixz="0.0" iyy="0.00013166666666666668" iyz="0.0" izz="0.00025000000000000006"/>
    </inertial>
  </link>
  <joint name="wheel_left_joint" type="continuous">
    <parent link="base_link"/>
    <child link="wheel_left_link"/>
    <origin rpy="0 0 0" xyz="0.12 0.18 -0.05"/>
    <axis xyz="0 1 0"/>
  </joint>
  <link name="wheel_right_link">
    <visual>
      <origin rpy="1.5707963267948966 0 0" xyz="0 0 0"/>
      <geometry>
        <cylinder length="0.04" radius="0.1"/>
      </geometry>
      <material name="Cyan"/>
    </visual>
    <collision>
      <origin rpy="1.5707963267948966 0 0" xyz="0 0 0"/>
      <geometry>
        <cylinder length="0.04" radius="0.1"/>
      </geometry>
    </collision>
    <inertial>
      <origin rpy="0 0 0" xyz="0 0 0"/>
      <mass value="0.05"/>
      <inertia ixx="0.00013166666666666668" ixy="0.0" ixz="0.0" iyy="0.00013166666666666668" iyz="0.0" izz="0.00025000000000000006"/>
    </inertial>
  </link>
  <joint name="wheel_right_joint" type="continuous">
    <parent link="base_link"/>
    <child link="wheel_right_link"/>
    <origin rpy="0 0 0" xyz="0.12 -0.18 -0.05"/>
    <axis xyz="0 1 0"/>
  </joint>
  <!-- Caster Wheel -->
  <link name="front_caster">
    <visual>
      <geometry>
        <sphere radius="0.060000000000000026"/>
      </geometry>
      <material name="Green"/>
    </visual>
    <collision>
      <geometry>
        <sphere radius="0.060000000000000026"/>
      </geometry>
    </collision>
    <inertial>
      <origin rpy="0 0 0" xyz="0 0 0"/>
      <mass value="0.01"/>
      <inertia ixx="1.4400000000000011e-05" ixy="0.0" ixz="0.0" iyy="1.4400000000000011e-05" iyz="0.0" izz="1.4400000000000011e-05"/>
    </inertial>
  </link>
  <joint name="caster_joint" type="fixed">
    <parent link="base_link"/>
    <child link="front_caster"/>
    <origin rpy="0 0 0" xyz="-0.14 0.0 -0.09"/>
  </joint>
  <joint name="lidar_joint" type="fixed">
    <parent link="base_link"/>
    <child link="lidar_link"/>
    <origin rpy="0 0 0" xyz="-0.105 0 0.21000000000000002"/>
  </joint>
  <link name="lidar_link">
    <visual>
      <geometry>
        <cylinder length="0.04" radius="0.05"/>
      </geometry>
      <material name="Blue"/>
    </visual>
    <visual>
      <origin xyz="0 0 -0.07"/>
      <geometry>
        <cylinder length="0.1" radius="0.01"/>
      </geometry>
      <material name="Blue"/>
    </visual>
    <collision>
      <geometry>
        <cylinder length="0.04" radius="0.05"/>
      </geometry>
    </collision>
    <inertial>
      <origin rpy="0 0 0" xyz="0 0 0"/>
      <mass value="0.1"/>
      <inertia ixx="7.583333333333335e-05" ixy="0.0" ixz="0.0" iyy="7.583333333333335e-05" iyz="0.0" izz="0.00012500000000000003"/>
    </inertial>
  </link>
  <joint name="camera_joint" type="fixed">
    <parent link="base_link"/>
    <child link="camera_link"/>
    <origin rpy="0 0 0" xyz="0.105 0 0.155"/>
  </joint>
  <link name="camera_link">
    <visual>
      <geometry>
        <box size="0.010 0.03 0.03"/>
      </geometry>
      <material name="Red"/>
    </visual>
    <visual>
      <origin xyz="0 0 -0.04"/>
      <geometry>
        <cylinder length="0.05" radius="0.002"/>
      </geometry>
      <material name="Red"/>
    </visual>
  </link>
  <joint name="camera_optical_joint" type="fixed">
    <parent link="camera_link"/>
    <child link="camera_optical_link"/>
    <origin rpy="0 0 0" xyz="0 0 0"/>
  </joint>
  <link name="camera_optical_link"/>
  <joint name="imu_joint" type="fixed">
    <parent link="base_link"/>
    <child link="imu_link"/>
    <origin rpy="0 0 0" xyz="0.185 0 0.095"/>
  </joint>
  <link name="imu_link">
    <visual>
      <geometry>
        <box size="0.05 0.1 0.01"/>
      </geometry>
      <material name="Brown"/>
    </visual>
    <collision>
      <geometry>
        <box size="0.05 0.1 0.01"/>
      </geometry>
    </collision>
    <inertial>
      <origin rpy="0 0 0" xyz="0 0 0"/>
      <mass value="0.1"/>
      <inertia ixx="0.0001666666666666667" ixy="0.0" ixz="0.0" iyy="0.00010416666666666669" iyz="0.0" izz="0.00010416666666666669"/>
    </inertial>
  </link>
</robot>
<!-- xacro spb_urdf.xacro > spb_urdf.urdf -->
